<mujoco model="cf2_drone">
  <body name="cf2" pos="1.0 0.0 0.0" childclass="cf2" gravcomp="1">
    <!-- <freejoint/> -->
    <!-- <inertial pos="0 0 0" mass="0.0" diaginertia="2.3951e-5 2.3951e-5 3.2347e-5"/> -->
    <!-- <camera name="track" pos="-1 0 .5" xyaxes="0 -1 0 1 0 2" mode="trackcom"/> -->
    <camera name="track" mode="trackcom" pos="0 -3 0.3" xyaxes="1 0 0 0 0 1"/>


    <geom name="torso_geom" pos="0 0 0" rgba="0.0 0.0 0.0 0.0" size="0.25" type="sphere" conaffinity="1" contype="1"/>

    <geom type="mesh" mesh="cf2_0" rgba="0.7 0.5 0.3 1.0"/>
    <geom type="mesh" mesh="cf2_1" rgba="0.7 0.5 0.3 1.0"/>
    <geom type="mesh" mesh="cf2_2" rgba="0.7 0.5 0.3 1.0"/>
    <geom type="mesh" mesh="cf2_3" rgba="0.7 0.5 0.3 1.0"/>
    <geom type="mesh" mesh="cf2_4" rgba="0.7 0.5 0.3 1.0"/>
    <geom type="mesh" mesh="cf2_5" rgba="0.7 0.5 0.3 1.0"/>
    <geom type="mesh" mesh="cf2_6" rgba="0.7 0.5 0.3 1.0"/>

    <joint name="obj_slidex" type="slide" pos="0 0 0" axis="1 0 0" range="-100 100" damping="0.0"/>
    <joint name="obj_slidey" type="slide" pos="0 0 0" axis="0 1 0" range="-100 100" damping="0.0"/>
    <joint name="obj_slidez" type="slide" pos="0 0 0" axis="0 0 1" range="-100 100" damping="0.0"/>
  </body>
</mujoco>
