<mujoco model="CF2 scene">
  <compiler angle="degree" coordinate="local" inertiafromgeom="true"/>
  <option timestep="0.01" iterations="4"/>

  <custom>
    <!-- brax custom params -->
    <numeric data="8 8 2 1 0 0 0 8 8 8" name="init_qpos"/>
    <numeric data="1000" name="constraint_limit_stiffness"/>
    <numeric data="4000" name="constraint_stiffness"/>
    <numeric data="10" name="constraint_ang_damping"/>
    <numeric data="20" name="constraint_vel_damping"/>
    <numeric data="0.5" name="joint_scale_pos"/>
    <numeric data="0.2" name="joint_scale_ang"/>
    <numeric data="0.0" name="ang_damping"/>
    <numeric data="1" name="spring_mass_scale"/>
    <numeric data="1" name="spring_inertia_scale"/>
    <numeric data="15" name="solver_maxls"/>
  </custom>

  <include file="/home/tassos/phd/research/second-project/task-aware-skill-composition/achql/brax/envs/assets/cf2/cf2.xml"/>

  <statistic center="0 0 0.1" extent="0.2" meansize=".05"/>

  <visual>
    <headlight diffuse="0.6 0.6 0.6" ambient="0.3 0.3 0.3" specular="0 0 0"/>
    <rgba haze="0.15 0.25 0.35 1"/>
    <global azimuth="-20" elevation="-20" ellipsoidinertia="true"/>
  </visual>

  <asset>
    <texture type="skybox" builtin="gradient" rgb1="0.3 0.5 0.7" rgb2="0 0 0" width="512" height="3072"/>
    <texture type="2d" name="groundplane" builtin="checker" mark="edge" rgb1="0.2 0.3 0.4" rgb2="0.1 0.2 0.3"
      markrgb="0.8 0.8 0.8" width="300" height="300"/>
    <material name="groundplane" texture="groundplane" texuniform="true" texrepeat="5 5" reflectance="0.2"/>
  </asset>

  <worldbody>
    <light pos="0 0 1.5" dir="0 0 -1" directional="true"/>
    <geom name="floor" size="0 0 0.05" type="plane" material="groundplane"/>

    <body name="target" pos="0 0 0.01" gravcomp="1">
        <joint armature="0" axis="1 0 0" damping="0" limited="true" name="target_x" pos="0 0 0" range="-100 100" stiffness="0" type="slide"/>
        <joint armature="0" axis="0 1 0" damping="0" limited="true" name="target_y" pos="0 0 0" range="-100 100" stiffness="0" type="slide"/>
        <joint armature="0" axis="0 0 1" damping="0" limited="true" name="target_z" pos="0 0 0" range="-100 100" stiffness="0" type="slide"/>
	<inertial pos="0 0 0" mass="1.0" diaginertia="2.3951e-5 2.3951e-5 3.2347e-5"/>
        <geom conaffinity="0" contype="0" name="target" pos="0 0 0" size=".9" type="sphere"/>
    </body>
  </worldbody>
</mujoco>
