<mujoco model="car">
  <compiler angle="degree" coordinate="local" inertiafromgeom="true"/>
  <option timestep="0.01" iterations="4"/>
  <custom>
    <!-- brax custom params -->
    <!-- <numeric data="0.0 0.0 0.55 1.0 0.0 0.0 0.0 0.0 1.0 0.0 -1.0 0.0 -1.0 0.0 1.0" name="init_qpos"/> -->
    <numeric data="10000" name="constraint_limit_stiffness"/>
    <numeric data="10000" name="constraint_stiffness"/>
    <numeric data="20" name="constraint_ang_damping"/>
    <numeric data="20" name="constraint_vel_damping"/>
    <numeric data="1" name="vel_damping"/>
    <numeric data="-0.05" name="ang_damping"/>
    <numeric data="1" name="spring_mass_scale"/>
    <numeric data="1" name="spring_inertia_scale"/>
    <numeric data="15" name="solver_maxls"/>
  </custom>
  <default>
    <geom contype="0" conaffinity="0" condim="3" density="5.0" friction="1 0.5 0.5"
	  rgba="0.4 0.33 0.26 1.0" size=".05" type="sphere"/>
    <joint armature="1" damping="1"/>
    <!-- <motor ctrlrange="-1 1" ctrllimited="true" forcerange="-.02 .02" forcelimited="true"/> -->
    <site size="0.032" type="sphere"/>
  </default>
  <asset>
    <texture builtin="gradient" height="100" rgb1="1 1 1" rgb2="0 0 0" type="skybox" width="100"/>
    <texture builtin="flat" height="1278" mark="cross" markrgb="1 1 1" name="texgeom" random="0.01" rgb1="0.8 0.6 0.4" rgb2="0.8 0.6 0.4" type="cube" width="127"/>
    <texture builtin="checker" height="100" name="texplane" rgb1="0 0 0" rgb2="0.8 0.8 0.8" type="2d" width="100"/>
    <material name="MatPlane" reflectance="0.5" shininess="1" specular="1" texrepeat="60 60" texture="texplane"/>
    <material name="geom" texture="texgeom" texuniform="true"/>
  </asset>
  <worldbody>
    <light cutoff="100" diffuse="1 1 1" dir="-0 0 -1.3" directional="true" exponent="1" pos="0 0 1.3" specular=".1 .1 .1"/>
    <geom conaffinity="1" condim="3" material="MatPlane" name="floor" pos="0 0 0" size="5 5 0.1" type="plane" rgba="0.5 0.5 0.5 1.0"/>

    <body name="robot" pos="0 0 0.20">
      <site name="robot" pos="0 0 0"/>
      <camera name="track" mode="trackcom" pos="0 -3 0.3" xyaxes="1 0 0 0 0 1"/>
      <geom name="robot_geom" pos="0 0 0" size=".1 .1 .05" type="box"/>
      <joint armature="0" damping="0" limited="false" margin="0.01" name="root" pos="0 0 0" type="free"/>

      <geom name="back_bumper" pos="0 .15 0" size=".1 .01 .05" type="box"/>
      <geom name="back_connector" pos="0 .125 0" size=".01 .025 .03" type="box"/>
      <geom name="front_bumper" pos="0 -.165 0" size=".05 .01 .05" type="box"/>
      <geom name="front_connector" pos="0 -.13 .04" size=".05 .03 .01" type="box"/>

      <body name="left_wheel" pos="-.1 .1 -.05">
        <joint name="left_wheel_joint" type="hinge" axis="1 0 0"/>
        <geom name="left_wheel_geom" contype="1" type="cylinder" fromto="-.055 0 0 -0.005 0 0"/>
      </body>

      <body name="right_wheel" pos=".1 .1 -.05">
        <joint name="right_wheel_joint" type="hinge" axis="1 0 0"/>
        <geom name="right_wheel_geom" contype="1" type="cylinder" fromto="0.005 0 0 .055 0 0"/>
      </body>

      <body name="rear_wheel" pos="0 -.1 -.05">
        <joint name="rear_wheel_joint" type="ball"/>
        <geom name="rear_wheel_geom" contype="1"/>
      </body>
    </body>
  </worldbody>
  <sensor>
    <jointvel joint="left_wheel_joint" name="jointvel_left_wheel"/>
    <jointvel joint="right_wheel_joint" name="jointvel_right_wheel"/>

    <ballquat joint="rear_wheel_joint" name="ballquat_rear"/>
    <ballangvel joint="rear_wheel_joint" name="ballangvel_rear"/>

    <!-- Used for observation -->
    <accelerometer site="robot" name="accelerometer"/>
    <velocimeter site="robot" name="velocimeter"/>
    <gyro site="robot" name="gyro"/>
    <magnetometer site="robot" name="magnetometer"/>

    <!-- Used for intrinsic constraints -->
    <subtreecom body="robot" name="subtreecom"/>
    <subtreelinvel body="robot" name="subtreelinvel"/>
    <subtreeangmom body="robot" name="subtreeangmom"/>
  </sensor>
  <actuator>
    <motor gear="1" jointinparent="left_wheel_joint" name="left_motor"/>
    <motor gear="1" jointinparent="right_wheel_joint" name="right_motor"/>
  </actuator>
</mujoco>
