<mujoco model="point">
  <compiler angle="radian" inertiafromgeom="true"/>
  <default>
    <geom condim="3" density="1" rgba="0.4 0.33 0.26 1.0"/>
    <joint damping="1"/>
    <motor ctrlrange="-1 1" ctrllimited="true" forcerange="-.05 .05" forcelimited="true"/>
    <velocity ctrlrange="-1 1" ctrllimited="true" forcerange="-.05 .05" forcelimited="true"/>
  </default>
  <!-- Removed RK4 integrator for brax. -->
  <option gravity="0 0 -9.81" timestep="0.01" />
  <custom>
    <!-- brax custom params -->
    <!-- <numeric data="0.0 0.0 0.55 1.0 0.0 0.0 0.0 0.0 1.0 0.0 -1.0 0.0 -1.0 0.0 1.0" name="init_qpos"/> -->
    <numeric data="1000" name="constraint_limit_stiffness"/>
    <numeric data="1000" name="constraint_stiffness"/>
    <numeric data="0.1" name="constraint_vel_damping"/>
    <numeric data="0.1" name="constraint_ang_damping"/>
    <numeric data="0.0" name="ang_damping"/>
    <numeric data="0" name="spring_mass_scale"/>
    <numeric data="1" name="spring_inertia_scale"/>
    <numeric data="5" name="solver_maxls"/>
  </custom>
  <asset>
    <texture builtin="gradient" height="100" rgb1="1 1 1" rgb2="0 0 0" type="skybox" width="100"/>
    <texture builtin="flat" height="1278" mark="cross" markrgb="1 1 1" name="texgeom" random="0.01" rgb1="0.8 0.6 0.4" rgb2="0.8 0.6 0.4" type="cube" width="127"/>
    <texture builtin="checker" height="100" name="texplane" rgb1="0 0 0" rgb2="0.8 0.8 0.8" type="2d" width="100"/>
    <material name="MatPlane" reflectance="0.5" shininess="1" specular="1" texrepeat="60 60" texture="texplane"/>
    <material name="geom" texture="texgeom" texuniform="true"/>
  </asset>
  <worldbody>
    <light cutoff="100" diffuse="1 1 1" dir="-0 0 -1.3" directional="true" exponent="1" pos="0 0 1.3" specular=".1 .1 .1"/>
    <geom conaffinity="1" condim="3" material="MatPlane" name="floor" pos="0 0 0" size="5 5 0.1" type="plane" rgba="0.5 0.5 0.5 1.0"/>
    <camera name="overview" pos="0 -5 5" xyaxes="1 0 0 0 .4 1" fovy="90"/>
    <body name="robot" pos="0 0 .1">
      <camera name="vision" pos="0 0 .15" xyaxes="0 -1 0 .4 0 1" fovy="90"/>
      <camera name="track" mode="trackcom" pos="0 -3 0.3" xyaxes="1 0 0 0 0 1"/>
      <!-- <geom name="camera" pos="-.2 0 0" type="sphere" size=".05"/> -->
      <joint type="slide" axis="1 0 0" name="x" damping="0.01"/>
      <joint type="slide" axis="0 1 0" name="y" damping="0.01"/>
      <joint type="hinge" axis="0 0 1" name="z" damping="0.005"/>
      <geom name="robot" type="sphere" size=".1" friction="1 0.01 0.01"/>
      <geom name="pointarrow" pos="0.1 0 0" size="0.05 0.05 0.05" type="box"/>
      <site name="robot" size="0.032" type="sphere" rgba="1 0 0 .1"/>
    </body>
  </worldbody>
  <sensor>
    <!-- Used for observation -->
    <accelerometer site="robot" name="accelerometer"/>
    <velocimeter site="robot" name="velocimeter"/>
    <gyro site="robot" name="gyro"/>
    <magnetometer site="robot" name="magnetometer"/>

    <!-- Used for intrinsic constraints -->
    <subtreecom body="robot" name="subtreecom"/>
    <subtreelinvel body="robot" name="subtreelinvel"/>
    <subtreeangmom body="robot" name="subtreeangmom"/>
  </sensor>
  <actuator>
    <!-- forward velocity -->
    <motor gear="0.03 0 0 0 0 0" site="robot" name="x"/>

    <!-- turning velocity -->
    <velocity gear="0.06" jointinparent="z" name="z"/>
  </actuator>
</mujoco>
