<mujoco model="ant">
  <compiler angle="degree" coordinate="local" inertiafromgeom="true"/>
  <option timestep="0.01" iterations="4" />
  <custom>
    <!-- brax custom params -->
    <!-- <numeric data="0 0 0.55 1.0 0.0 0.0 0.0 0.0 1.0 0.0 -1.0 0.0 -1.0 0.0 1.0 0.0 0.0" name="init_qpos"/> -->
    <numeric data="1000" name="constraint_limit_stiffness"/>
    <numeric data="4000" name="constraint_stiffness"/>
    <numeric data="10" name="constraint_ang_damping"/>
    <numeric data="20" name="constraint_vel_damping"/>
    <numeric data="0.5" name="joint_scale_pos"/>
    <numeric data="0.2" name="joint_scale_ang"/>
    <numeric data="0.0" name="ang_damping"/>
    <numeric data="1" name="spring_mass_scale"/>
    <numeric data="1" name="spring_inertia_scale"/>
    <numeric data="15" name="solver_maxls"/>
  </custom>
  <default>
    <joint armature="1" damping="1" limited="true"/>
    <geom contype="0" conaffinity="0" condim="3" density="5.0" friction="1 0.5 0.5"/>

    <default class="cf2">
      <default class="visual">
        <geom group="2" type="mesh" contype="0" conaffinity="0"/>
      </default>
      <default class="collision">
        <geom group="3" type="mesh"/>
      </default>
      <site group="5"/>
    </default>
  </default>
  <asset>
    <material name="polished_plastic" rgba="0.631 0.659 0.678 1"/>
    <material name="polished_gold" rgba="0.969 0.878 0.6 1"/>
    <material name="medium_gloss_plastic" rgba="0.109 0.184 0.0 1"/>
    <material name="propeller_plastic" rgba="0.792 0.820 0.933 1"/>
    <material name="white" rgba="1 1 1 1"/>
    <material name="body_frame_plastic" rgba="0.102 0.102 0.102 1"/>
    <material name="burnished_chrome" rgba="0.898 0.898 0.898 1"/>

    <mesh file="/home/tassos/phd/research/second-project/task-aware-skill-composition/task_aware_skill_composition/brax/envs/assets/cf2/meshes/cf2_0.obj" scale="10 10 10"/>
    <mesh file="/home/tassos/phd/research/second-project/task-aware-skill-composition/task_aware_skill_composition/brax/envs/assets/cf2/meshes/cf2_1.obj" scale="10 10 10"/>
    <mesh file="/home/tassos/phd/research/second-project/task-aware-skill-composition/task_aware_skill_composition/brax/envs/assets/cf2/meshes/cf2_2.obj" scale="10 10 10"/>
    <mesh file="/home/tassos/phd/research/second-project/task-aware-skill-composition/task_aware_skill_composition/brax/envs/assets/cf2/meshes/cf2_3.obj" scale="10 10 10"/>
    <mesh file="/home/tassos/phd/research/second-project/task-aware-skill-composition/task_aware_skill_composition/brax/envs/assets/cf2/meshes/cf2_4.obj" scale="10 10 10"/>
    <mesh file="/home/tassos/phd/research/second-project/task-aware-skill-composition/task_aware_skill_composition/brax/envs/assets/cf2/meshes/cf2_5.obj" scale="10 10 10"/>
    <mesh file="/home/tassos/phd/research/second-project/task-aware-skill-composition/task_aware_skill_composition/brax/envs/assets/cf2/meshes/cf2_6.obj" scale="10 10 10"/>
    <mesh file="/home/tassos/phd/research/second-project/task-aware-skill-composition/task_aware_skill_composition/brax/envs/assets/cf2/meshes/cf2_collision_0.obj" scale="10 10 10"/>
    <mesh file="/home/tassos/phd/research/second-project/task-aware-skill-composition/task_aware_skill_composition/brax/envs/assets/cf2/meshes/cf2_collision_1.obj" scale="10 10 10"/>
    <mesh file="/home/tassos/phd/research/second-project/task-aware-skill-composition/task_aware_skill_composition/brax/envs/assets/cf2/meshes/cf2_collision_2.obj" scale="10 10 10"/>
    <mesh file="/home/tassos/phd/research/second-project/task-aware-skill-composition/task_aware_skill_composition/brax/envs/assets/cf2/meshes/cf2_collision_3.obj" scale="10 10 10"/>
    <mesh file="/home/tassos/phd/research/second-project/task-aware-skill-composition/task_aware_skill_composition/brax/envs/assets/cf2/meshes/cf2_collision_4.obj" scale="10 10 10"/>
    <mesh file="/home/tassos/phd/research/second-project/task-aware-skill-composition/task_aware_skill_composition/brax/envs/assets/cf2/meshes/cf2_collision_5.obj" scale="10 10 10"/>
    <mesh file="/home/tassos/phd/research/second-project/task-aware-skill-composition/task_aware_skill_composition/brax/envs/assets/cf2/meshes/cf2_collision_6.obj" scale="10 10 10"/>
    <mesh file="/home/tassos/phd/research/second-project/task-aware-skill-composition/task_aware_skill_composition/brax/envs/assets/cf2/meshes/cf2_collision_7.obj" scale="10 10 10"/>
    <mesh file="/home/tassos/phd/research/second-project/task-aware-skill-composition/task_aware_skill_composition/brax/envs/assets/cf2/meshes/cf2_collision_8.obj" scale="10 10 10"/>
    <mesh file="/home/tassos/phd/research/second-project/task-aware-skill-composition/task_aware_skill_composition/brax/envs/assets/cf2/meshes/cf2_collision_9.obj" scale="10 10 10"/>
    <mesh file="/home/tassos/phd/research/second-project/task-aware-skill-composition/task_aware_skill_composition/brax/envs/assets/cf2/meshes/cf2_collision_10.obj" scale="10 10 10"/>
    <mesh file="/home/tassos/phd/research/second-project/task-aware-skill-composition/task_aware_skill_composition/brax/envs/assets/cf2/meshes/cf2_collision_11.obj" scale="10 10 10"/>
    <mesh file="/home/tassos/phd/research/second-project/task-aware-skill-composition/task_aware_skill_composition/brax/envs/assets/cf2/meshes/cf2_collision_12.obj" scale="10 10 10"/>
    <mesh file="/home/tassos/phd/research/second-project/task-aware-skill-composition/task_aware_skill_composition/brax/envs/assets/cf2/meshes/cf2_collision_13.obj" scale="10 10 10"/>
    <mesh file="/home/tassos/phd/research/second-project/task-aware-skill-composition/task_aware_skill_composition/brax/envs/assets/cf2/meshes/cf2_collision_14.obj" scale="10 10 10"/>
    <mesh file="/home/tassos/phd/research/second-project/task-aware-skill-composition/task_aware_skill_composition/brax/envs/assets/cf2/meshes/cf2_collision_15.obj" scale="10 10 10"/>
    <mesh file="/home/tassos/phd/research/second-project/task-aware-skill-composition/task_aware_skill_composition/brax/envs/assets/cf2/meshes/cf2_collision_16.obj" scale="10 10 10"/>
    <mesh file="/home/tassos/phd/research/second-project/task-aware-skill-composition/task_aware_skill_composition/brax/envs/assets/cf2/meshes/cf2_collision_17.obj" scale="10 10 10"/>
    <mesh file="/home/tassos/phd/research/second-project/task-aware-skill-composition/task_aware_skill_composition/brax/envs/assets/cf2/meshes/cf2_collision_18.obj" scale="10 10 10"/>
    <mesh file="/home/tassos/phd/research/second-project/task-aware-skill-composition/task_aware_skill_composition/brax/envs/assets/cf2/meshes/cf2_collision_19.obj" scale="10 10 10"/>
    <mesh file="/home/tassos/phd/research/second-project/task-aware-skill-composition/task_aware_skill_composition/brax/envs/assets/cf2/meshes/cf2_collision_20.obj" scale="10 10 10"/>
    <mesh file="/home/tassos/phd/research/second-project/task-aware-skill-composition/task_aware_skill_composition/brax/envs/assets/cf2/meshes/cf2_collision_21.obj" scale="10 10 10"/>
    <mesh file="/home/tassos/phd/research/second-project/task-aware-skill-composition/task_aware_skill_composition/brax/envs/assets/cf2/meshes/cf2_collision_22.obj" scale="10 10 10"/>
    <mesh file="/home/tassos/phd/research/second-project/task-aware-skill-composition/task_aware_skill_composition/brax/envs/assets/cf2/meshes/cf2_collision_23.obj" scale="10 10 10"/>
    <mesh file="/home/tassos/phd/research/second-project/task-aware-skill-composition/task_aware_skill_composition/brax/envs/assets/cf2/meshes/cf2_collision_24.obj" scale="10 10 10"/>
    <mesh file="/home/tassos/phd/research/second-project/task-aware-skill-composition/task_aware_skill_composition/brax/envs/assets/cf2/meshes/cf2_collision_25.obj" scale="10 10 10"/>
    <mesh file="/home/tassos/phd/research/second-project/task-aware-skill-composition/task_aware_skill_composition/brax/envs/assets/cf2/meshes/cf2_collision_26.obj" scale="10 10 10"/>
    <mesh file="/home/tassos/phd/research/second-project/task-aware-skill-composition/task_aware_skill_composition/brax/envs/assets/cf2/meshes/cf2_collision_27.obj" scale="10 10 10"/>
    <mesh file="/home/tassos/phd/research/second-project/task-aware-skill-composition/task_aware_skill_composition/brax/envs/assets/cf2/meshes/cf2_collision_28.obj" scale="10 10 10"/>
    <mesh file="/home/tassos/phd/research/second-project/task-aware-skill-composition/task_aware_skill_composition/brax/envs/assets/cf2/meshes/cf2_collision_29.obj" scale="10 10 10"/>
    <mesh file="/home/tassos/phd/research/second-project/task-aware-skill-composition/task_aware_skill_composition/brax/envs/assets/cf2/meshes/cf2_collision_30.obj" scale="10 10 10"/>
    <mesh file="/home/tassos/phd/research/second-project/task-aware-skill-composition/task_aware_skill_composition/brax/envs/assets/cf2/meshes/cf2_collision_31.obj" scale="10 10 10"/>

    <texture builtin="gradient" height="100" rgb1="1 1 1" rgb2="1 1 1" type="skybox" width="100"/>
    <texture builtin="flat" height="1278" mark="cross" markrgb="1 1 1" name="texgeom" random="0.01" rgb1="0.8 0.6 0.4" rgb2="0.8 0.6 0.4" type="cube" width="127"/>
    <texture builtin="checker" height="100" name="texplane" rgb1="0.8 0.8 0.8" rgb2="0.8 0.8 0.8" type="2d" width="100"/>
    <material name="MatPlane" reflectance="0.0" shininess="1" specular="1" texrepeat="60 60" texture="texplane"/>
    <material name="geom" texture="texgeom" texuniform="true"/>
  </asset>

  <worldbody>
    <light cutoff="100" diffuse="1 1 1" dir="-0 0 -1.3" directional="true" exponent="1" pos="0 0 1.3" specular=".1 .1 .1"/>
    <!-- <geom conaffinity="1" condim="3" material="MatPlane" name="floor" pos="0 0 0" size="100 100 40" type="plane"/> -->
    <light cutoff="100" diffuse="1 1 1" dir="0 1.3 0" directional="true" exponent="1" pos="8 -5.5 8" specular=".1 .1 .1"/>
    <camera name="overview" pos="8 -5.5 8" xyaxes="1 0 0 0 0 1" fovy="110"/>

    <include file="/home/tassos/phd/research/second-project/task-aware-skill-composition/task_aware_skill_composition/brax/envs/assets/cf2/cf2_drone.xml"/>

    <!-- <body name="torso" pos="0 0 0.75" gravcomp="1"> -->
    <!--   <!-\- <camera name="track" mode="trackcom" pos="0 -3 0.3" xyaxes="1 0 0 0 0 1"/> -\-> -->
    <!--   <geom name="torso_geom" pos="0 0 0" rgba="0.7 0.5 0.3 1.0" size="0.25" type="sphere" conaffinity="1" contype="1"/> -->
    <!--   <!-\- <joint armature="0" damping="0" limited="false" margin="0.01" name="root" pos="0 0 0" type="free"/> -\-> -->

    <!--   <joint name="obj_slidex" type="slide" pos="0 0 0" axis="1 0 0" range="-100 100" damping="0.0"/> -->
    <!--   <joint name="obj_slidey" type="slide" pos="0 0 0" axis="0 1 0" range="-100 100" damping="0.0"/> -->
    <!--   <joint name="obj_slidez" type="slide" pos="0 0 0" axis="0 0 1" range="-100 100" damping="0.0"/> -->
    <!-- </body> -->

    <!-- <body name="subgoal" pos="12.0 4.0 2.0"> -->
    <!--     <geom conaffinity="0" contype="0" pos="0 0 0" rgba="0.3 0.3 0.7 1.0" size=".9" type="sphere"  mass="1.0"/> -->
    <!-- </body> -->

    <body name="center_obstacle">
        <geom conaffinity="0" contype="0" pos="8 8 6" size="2.0" rgba="0.7 0.3 0.3 0.5" type="sphere"/>
    </body>

    <body name="target" pos="0 0 0.01" gravcomp="1">
        <joint armature="0" axis="1 0 0" damping="0" limited="true" name="target_x" pos="0 0 0" range="-100 100" stiffness="0" type="slide"/>
        <joint armature="0" axis="0 1 0" damping="0" limited="true" name="target_y" pos="0 0 0" range="-100 100" stiffness="0" type="slide"/>
        <joint armature="0" axis="0 0 1" damping="0" limited="true" name="target_z" pos="0 0 0" range="-100 100" stiffness="0" type="slide"/>
        <geom conaffinity="0" contype="0" name="target" pos="0 0 0" rgba="0.3 0.7 0.3 1.0" size=".9" type="sphere"  mass="1.0"/>
    </body>
  </worldbody>

  <actuator>
    <motor name="move_x" joint="obj_slidex" gear="5 0 0"/>
    <motor name="move_y" joint="obj_slidey" gear="5 0 0"/>
    <motor name="move_z" joint="obj_slidez" gear="5 0 0"/>
  </actuator>
</mujoco>
